Unauthorized: /api/token/
Unauthorized: /api/token/
Unauthorized: /api/token/
Unauthorized: /api/token/
Unauthorized: /api/token/
Unauthorized: /api/token/
Not Found: /create
Unauthorized: /api/token/
Unauthorized: /api/items/1/
Unauthorized: /api/items/1/
Unauthorized: /api/items/{1}/
Unauthorized: /api/items/1/
Internal Server Error: /api/items/2/
Traceback (most recent call last):
  File "C:\Users\GAURAV\Desktop\inventory_management\venv\lib\site-packages\django_redis\cache.py", line 29, in _decorator
    return method(self, *args, **kwargs)
  File "C:\Users\GAURAV\Desktop\inventory_management\venv\lib\site-packages\django_redis\cache.py", line 99, in _get
    return self.client.get(key, default=default, version=version, client=client)
  File "C:\Users\GAURAV\Desktop\inventory_management\venv\lib\site-packages\django_redis\client\default.py", line 260, in get
    raise ConnectionInterrupted(connection=client) from e
django_redis.exceptions.ConnectionInterrupted: Redis ConnectionError: Error 10061 connecting to 127.0.0.1:6379. No connection could be made because the target machine actively refused it.

During handling of the above exception, another exception occurred:

Traceback (most recent call last):
  File "C:\Users\GAURAV\Desktop\inventory_management\venv\lib\site-packages\django\core\handlers\exception.py", line 55, in inner
    response = get_response(request)
  File "C:\Users\GAURAV\Desktop\inventory_management\venv\lib\site-packages\django\core\handlers\base.py", line 197, in _get_response
    response = wrapped_callback(request, *callback_args, **callback_kwargs)
  File "C:\Users\GAURAV\Desktop\inventory_management\venv\lib\site-packages\django\views\decorators\csrf.py", line 65, in _view_wrapper
    return view_func(request, *args, **kwargs)
  File "C:\Users\GAURAV\Desktop\inventory_management\venv\lib\site-packages\rest_framework\viewsets.py", line 124, in view
    return self.dispatch(request, *args, **kwargs)
  File "C:\Users\GAURAV\Desktop\inventory_management\venv\lib\site-packages\rest_framework\views.py", line 509, in dispatch
    response = self.handle_exception(exc)
  File "C:\Users\GAURAV\Desktop\inventory_management\venv\lib\site-packages\rest_framework\views.py", line 469, in handle_exception
    self.raise_uncaught_exception(exc)
  File "C:\Users\GAURAV\Desktop\inventory_management\venv\lib\site-packages\rest_framework\views.py", line 480, in raise_uncaught_exception
    raise exc
  File "C:\Users\GAURAV\Desktop\inventory_management\venv\lib\site-packages\rest_framework\views.py", line 506, in dispatch
    response = handler(request, *args, **kwargs)
  File "C:\Users\GAURAV\Desktop\inventory_management\inventory\views.py", line 33, in retrieve
    item = cache.get(f'item_{pk}')
  File "C:\Users\GAURAV\Desktop\inventory_management\venv\lib\site-packages\django_redis\cache.py", line 92, in get
    value = self._get(key, default, version, client)
  File "C:\Users\GAURAV\Desktop\inventory_management\venv\lib\site-packages\django_redis\cache.py", line 36, in _decorator
    raise e.__cause__
  File "C:\Users\GAURAV\Desktop\inventory_management\venv\lib\site-packages\django_redis\client\default.py", line 258, in get
    value = client.get(key)
  File "C:\Users\GAURAV\Desktop\inventory_management\venv\lib\site-packages\redis\commands\core.py", line 1822, in get
    return self.execute_command("GET", name, keys=[name])
  File "C:\Users\GAURAV\Desktop\inventory_management\venv\lib\site-packages\redis\client.py", line 559, in execute_command
    return self._execute_command(*args, **options)
  File "C:\Users\GAURAV\Desktop\inventory_management\venv\lib\site-packages\redis\client.py", line 565, in _execute_command
    conn = self.connection or pool.get_connection(command_name, **options)
  File "C:\Users\GAURAV\Desktop\inventory_management\venv\lib\site-packages\redis\connection.py", line 1423, in get_connection
    connection.connect()
  File "C:\Users\GAURAV\Desktop\inventory_management\venv\lib\site-packages\redis\connection.py", line 364, in connect
    raise ConnectionError(self._error_message(e))
redis.exceptions.ConnectionError: Error 10061 connecting to 127.0.0.1:6379. No connection could be made because the target machine actively refused it.
Unauthorized: /api/items/2/
Unauthorized: /api/items/2/
Unauthorized: /api/items/2/
